<?xml version="1.0"?>
<robot name="hexapod">
  <link name="body">
    <inertial>
      <mass value="2.0"/>
      <inertia ixx="0.1" ixy="0" ixz="0" iyy="0.1" iyz="0" izz="0.1"/>
    </inertial>
  </link>

  <link name="leg_0_coxa">
    <inertial>
      <mass value="0.1"/>
      <inertia ixx="0.001" ixy="0" ixz="0" iyy="0.001" iyz="0" izz="0.001"/>
    </inertial>
  </link>
  
  <link name="leg_0_femur">
    <inertial>
      <mass value="0.08"/>
      <inertia ixx="0.001" ixy="0" ixz="0" iyy="0.001" iyz="0" izz="0.001"/>
    </inertial>
  </link>
  
  <link name="leg_0_tibia">
    <inertial>
      <mass value="0.05"/>
      <inertia ixx="0.0005" ixy="0" ixz="0" iyy="0.0005" iyz="0" izz="0.0005"/>
    </inertial>
  </link>
  
  <joint name="leg_0_coxa_joint" type="revolute">
    <parent link="body"/>
    <child link="leg_0_coxa"/>
    <origin xyz="0.15 0.1 0" rpy="0 0 0"/>
    <axis xyz="0 0 1"/>
    <limit lower="-1.57" upper="1.57" effort="5" velocity="2"/>
  </joint>
  
  <joint name="leg_0_femur_joint" type="revolute">
    <parent link="leg_0_coxa"/>
    <child link="leg_0_femur"/>
    <origin xyz="0.05 0 0" rpy="0 0 0"/>
    <axis xyz="0 1 0"/>
    <limit lower="-1.57" upper="1.57" effort="5" velocity="2"/>
  </joint>
  
  <joint name="leg_0_tibia_joint" type="revolute">
    <parent link="leg_0_femur"/>
    <child link="leg_0_tibia"/>
    <origin xyz="0.1 0 0" rpy="0 0 0"/>
    <axis xyz="0 1 0"/>
    <limit lower="-1.57" upper="1.57" effort="5" velocity="2"/>
  </joint>

  <link name="leg_1_coxa">
    <inertial>
      <mass value="0.1"/>
      <inertia ixx="0.001" ixy="0" ixz="0" iyy="0.001" iyz="0" izz="0.001"/>
    </inertial>
  </link>
  
  <link name="leg_1_femur">
    <inertial>
      <mass value="0.08"/>
      <inertia ixx="0.001" ixy="0" ixz="0" iyy="0.001" iyz="0" izz="0.001"/>
    </inertial>
  </link>
  
  <link name="leg_1_tibia">
    <inertial>
      <mass value="0.05"/>
      <inertia ixx="0.0005" ixy="0" ixz="0" iyy="0.0005" iyz="0" izz="0.0005"/>
    </inertial>
  </link>
  
  <joint name="leg_1_coxa_joint" type="revolute">
    <parent link="body"/>
    <child link="leg_1_coxa"/>
    <origin xyz="0.15 -0.1 0" rpy="0 0 0"/>
    <axis xyz="0 0 1"/>
    <limit lower="-1.57" upper="1.57" effort="5" velocity="2"/>
  </joint>
  
  <joint name="leg_1_femur_joint" type="revolute">
    <parent link="leg_1_coxa"/>
    <child link="leg_1_femur"/>
    <origin xyz="0.05 0 0" rpy="0 0 0"/>
    <axis xyz="0 1 0"/>
    <limit lower="-1.57" upper="1.57" effort="5" velocity="2"/>
  </joint>
  
  <joint name="leg_1_tibia_joint" type="revolute">
    <parent link="leg_1_femur"/>
    <child link="leg_1_tibia"/>
    <origin xyz="0.1 0 0" rpy="0 0 0"/>
    <axis xyz="0 1 0"/>
    <limit lower="-1.57" upper="1.57" effort="5" velocity="2"/>
  </joint>

  <link name="leg_2_coxa">
    <inertial>
      <mass value="0.1"/>
      <inertia ixx="0.001" ixy="0" ixz="0" iyy="0.001" iyz="0" izz="0.001"/>
    </inertial>
  </link>
  
  <link name="leg_2_femur">
    <inertial>
      <mass value="0.08"/>
      <inertia ixx="0.001" ixy="0" ixz="0" iyy="0.001" iyz="0" izz="0.001"/>
    </inertial>
  </link>
  
  <link name="leg_2_tibia">
    <inertial>
      <mass value="0.05"/>
      <inertia ixx="0.0005" ixy="0" ixz="0" iyy="0.0005" iyz="0" izz="0.0005"/>
    </inertial>
  </link>
  
  <joint name="leg_2_coxa_joint" type="revolute">
    <parent link="body"/>
    <child link="leg_2_coxa"/>
    <origin xyz="0 0.15 0" rpy="0 0 0"/>
    <axis xyz="0 0 1"/>
    <limit lower="-1.57" upper="1.57" effort="5" velocity="2"/>
  </joint>
  
  <joint name="leg_2_femur_joint" type="revolute">
    <parent link="leg_2_coxa"/>
    <child link="leg_2_femur"/>
    <origin xyz="0.05 0 0" rpy="0 0 0"/>
    <axis xyz="0 1 0"/>
    <limit lower="-1.57" upper="1.57" effort="5" velocity="2"/>
  </joint>
  
  <joint name="leg_2_tibia_joint" type="revolute">
    <parent link="leg_2_femur"/>
    <child link="leg_2_tibia"/>
    <origin xyz="0.1 0 0" rpy="0 0 0"/>
    <axis xyz="0 1 0"/>
    <limit lower="-1.57" upper="1.57" effort="5" velocity="2"/>
  </joint>

  <link name="leg_3_coxa">
    <inertial>
      <mass value="0.1"/>
      <inertia ixx="0.001" ixy="0" ixz="0" iyy="0.001" iyz="0" izz="0.001"/>
    </inertial>
  </link>
  
  <link name="leg_3_femur">
    <inertial>
      <mass value="0.08"/>
      <inertia ixx="0.001" ixy="0" ixz="0" iyy="0.001" iyz="0" izz="0.001"/>
    </inertial>
  </link>
  
  <link name="leg_3_tibia">
    <inertial>
      <mass value="0.05"/>
      <inertia ixx="0.0005" ixy="0" ixz="0" iyy="0.0005" iyz="0" izz="0.0005"/>
    </inertial>
  </link>
  
  <joint name="leg_3_coxa_joint" type="revolute">
    <parent link="body"/>
    <child link="leg_3_coxa"/>
    <origin xyz="0 -0.15 0" rpy="0 0 0"/>
    <axis xyz="0 0 1"/>
    <limit lower="-1.57" upper="1.57" effort="5" velocity="2"/>
  </joint>
  
  <joint name="leg_3_femur_joint" type="revolute">
    <parent link="leg_3_coxa"/>
    <child link="leg_3_femur"/>
    <origin xyz="0.05 0 0" rpy="0 0 0"/>
    <axis xyz="0 1 0"/>
    <limit lower="-1.57" upper="1.57" effort="5" velocity="2"/>
  </joint>
  
  <joint name="leg_3_tibia_joint" type="revolute">
    <parent link="leg_3_femur"/>
    <child link="leg_3_tibia"/>
    <origin xyz="0.1 0 0" rpy="0 0 0"/>
    <axis xyz="0 1 0"/>
    <limit lower="-1.57" upper="1.57" effort="5" velocity="2"/>
  </joint>

  <link name="leg_4_coxa">
    <inertial>
      <mass value="0.1"/>
      <inertia ixx="0.001" ixy="0" ixz="0" iyy="0.001" iyz="0" izz="0.001"/>
    </inertial>
  </link>
  
  <link name="leg_4_femur">
    <inertial>
      <mass value="0.08"/>
      <inertia ixx="0.001" ixy="0" ixz="0" iyy="0.001" iyz="0" izz="0.001"/>
    </inertial>
  </link>
  
  <link name="leg_4_tibia">
    <inertial>
      <mass value="0.05"/>
      <inertia ixx="0.0005" ixy="0" ixz="0" iyy="0.0005" iyz="0" izz="0.0005"/>
    </inertial>
  </link>
  
  <joint name="leg_4_coxa_joint" type="revolute">
    <parent link="body"/>
    <child link="leg_4_coxa"/>
    <origin xyz="-0.15 0.1 0" rpy="0 0 0"/>
    <axis xyz="0 0 1"/>
    <limit lower="-1.57" upper="1.57" effort="5" velocity="2"/>
  </joint>
  
  <joint name="leg_4_femur_joint" type="revolute">
    <parent link="leg_4_coxa"/>
    <child link="leg_4_femur"/>
    <origin xyz="0.05 0 0" rpy="0 0 0"/>
    <axis xyz="0 1 0"/>
    <limit lower="-1.57" upper="1.57" effort="5" velocity="2"/>
  </joint>
  
  <joint name="leg_4_tibia_joint" type="revolute">
    <parent link="leg_4_femur"/>
    <child link="leg_4_tibia"/>
    <origin xyz="0.1 0 0" rpy="0 0 0"/>
    <axis xyz="0 1 0"/>
    <limit lower="-1.57" upper="1.57" effort="5" velocity="2"/>
  </joint>

  <link name="leg_5_coxa">
    <inertial>
      <mass value="0.1"/>
      <inertia ixx="0.001" ixy="0" ixz="0" iyy="0.001" iyz="0" izz="0.001"/>
    </inertial>
  </link>
  
  <link name="leg_5_femur">
    <inertial>
      <mass value="0.08"/>
      <inertia ixx="0.001" ixy="0" ixz="0" iyy="0.001" iyz="0" izz="0.001"/>
    </inertial>
  </link>
  
  <link name="leg_5_tibia">
    <inertial>
      <mass value="0.05"/>
      <inertia ixx="0.0005" ixy="0" ixz="0" iyy="0.0005" iyz="0" izz="0.0005"/>
    </inertial>
  </link>
  
  <joint name="leg_5_coxa_joint" type="revolute">
    <parent link="body"/>
    <child link="leg_5_coxa"/>
    <origin xyz="-0.15 -0.1 0" rpy="0 0 0"/>
    <axis xyz="0 0 1"/>
    <limit lower="-1.57" upper="1.57" effort="5" velocity="2"/>
  </joint>
  
  <joint name="leg_5_femur_joint" type="revolute">
    <parent link="leg_5_coxa"/>
    <child link="leg_5_femur"/>
    <origin xyz="0.05 0 0" rpy="0 0 0"/>
    <axis xyz="0 1 0"/>
    <limit lower="-1.57" upper="1.57" effort="5" velocity="2"/>
  </joint>
  
  <joint name="leg_5_tibia_joint" type="revolute">
    <parent link="leg_5_femur"/>
    <child link="leg_5_tibia"/>
    <origin xyz="0.1 0 0" rpy="0 0 0"/>
    <axis xyz="0 1 0"/>
    <limit lower="-1.57" upper="1.57" effort="5" velocity="2"/>
  </joint>
</robot>